Workbook

Sheet Note1
B1: ວັນທີ | C1: code2 | E1: ນໍ້າດື່ມ | F1: ເນື້ອໃນ | G1: ຈ່າຍ | H1: ຈ່າຍ | I1: ຈ່າຍ | J1: ຈ່າຍ | K1: ຮັບ | L1: ຮັບ | M1: ຮັບ | N1: ຮັບ
A2: ງວດໄກ່ | B2: Date | C2: categories code | D2: Name Categories | E2: Sub categories | F2: Noted | G2: Kip | H2: Bath | I2: Us | J2: Yuan | K2: Kip | L2: Bath | M2: Us | N2: Yuan | O2: ໄລ່ເຂົ້າກໍາໄລແຕ່ລະງວດບໍ? | P2: Note
B3: 45316 | C3: 3 | D3: ຄ່າບໍລິຫານ | E3: ຕລາດ | F3: ຫວດ ຢາລ້າງຖ້ວຍ | G3: 397000 | O3: =IF(C3="","",IF(C3=5,IFERROR(INDEX(code_Note1!$F$13:$F$16,MATCH(E3,code_Note1!$E$13:$E$16,0)),INDEX(code_Note1!$F$16,1)),IF(B3<code_Note1!$D$21,"No",IFERROR(VLOOKUP(C3,code_Note1!$D$3:$G$8,3,FALSE),"")))) -> No | P3: ລາຍງ່າຍລະຫວ່າງໄລຍະເວລາໃນການເອົາໄກ່ເຂົ້າລະໄລ່ເຂົ້າໃນການບໍລິຫານຂາດທຶນກໍາໄລໄກ່ຊຸດນັ້ນໆ
B4: 45316 | C4: 2 | D4: ຄ່າກໍ່ສ້າງ ປັບປຸງສວນ | E4: ຊີມັງ ເລັກ | F4: ເຫັລກຊິມັງໄມ້ | G4: 8280000 | O4: =IF(C4="","",IF(C4=5,IFERROR(INDEX(code_Note1!$F$13:$F$16,MATCH(E4,code_Note1!$E$13:$E$16,0)),INDEX(code_Note1!$F$16,1)),IF(B4<code_Note1!$D$21,"No",IFERROR(VLOOKUP(C4,code_Note1!$D$3:$G$8,3,FALSE),"")))) -> No | P4: ເງິນກ້ອນເອົາມາລຶງທຶນ
B5: 45316 | C5: 3 | D5: ຄ່າບໍລິຫານ | E5: ຕລາດ | F5: ຕລາດ ຊີ້ນ | G5: 500000 | O5: =IF(C5="","",IF(C5=5,IFERROR(INDEX(code_Note1!$F$13:$F$16,MATCH(E5,code_Note1!$E$13:$E$16,0)),INDEX(code_Note1!$F$16,1)),IF(B5<code_Note1!$D$21,"No",IFERROR(VLOOKUP(C5,code_Note1!$D$3:$G$8,3,FALSE),"")))) -> No | P5: ລາຍງ່າຍລະຫວ່າງໄລຍະເວລາໃນການເອົາໄກ່ເຂົ້າລະໄລ່ເຂົ້າໃນການບໍລິຫານຂາດທຶນກໍາໄລໄກ່ຊຸດນັ້ນໆ
B6: 45316 | C6: 3 | D6: ຄ່າບໍລິຫານ | E6: ຕລາດ | F6: ອາຫານສວຍ | G6: 103000 | O6: =IF(C6="","",IF(C6=5,IFERROR(INDEX(code_Note1!$F$13:$F$16,MATCH(E6,code_Note1!$E$13:$E$16,0)),INDEX(code_Note1!$F$16,1)),IF(B6<code_Note1!$D$21,"No",IFERROR(VLOOKUP(C6,code_Note1!$D$3:$G$8,3,FALSE),"")))) -> No | P6: ລາຍງ່າຍລະຫວ່າງໄລຍະເວລາໃນການເອົາໄກ່ເຂົ້າລະໄລ່ເຂົ້າໃນການບໍລິຫານຂາດທຶນກໍາໄລໄກ່ຊຸດນັ້ນໆ
B7: 45316 | C7: 3 | D7: ຄ່າບໍລິຫານ | E7: ຕລາດ | F7: ຄົກ | G7: 100000 | O7: =IF(C7="","",IF(C7=5,IFERROR(INDEX(code_Note1!$F$13:$F$16,MATCH(E7,code_Note1!$E$13:$E$16,0)),INDEX(code_Note1!$F$16,1)),IF(B7<code_Note1!$D$21,"No",IFERROR(VLOOKUP(C7,code_Note1!$D$3:$G$8,3,FALSE),"")))) -> No | P7: ລາຍງ່າຍລະຫວ່າງໄລຍະເວລາໃນການເອົາໄກ່ເຂົ້າລະໄລ່ເຂົ້າໃນການບໍລິຫານຂາດທຶນກໍາໄລໄກ່ຊຸດນັ້ນໆ
B8: 45316 | C8: 2 | D8: ຄ່າກໍ່ສ້າງ ປັບປຸງສວນ | E8: ຖັງນໍ້າ | F8: ຖັງນໍ້າເຢັນ | G8: 1800000 | O8: =IF(C8="","",IF(C8=5,IFERROR(INDEX(code_Note1!$F$13:$F$16,MATCH(E8,code_Note1!$E$13:$E$16,0)),INDEX(code_Note1!$F$16,1)),IF(B8<code_Note1!$D$21,"No",IFERROR(VLOOKUP(C8,code_Note1!$D$3:$G$8,3,FALSE),"")))) -> No | P8: ເງິນກ້ອນເອົາມາລຶງທຶນ
B9: 45316 | C9: 2 | D9: ຄ່າກໍ່ສ້າງ ປັບປຸງສວນ | E9: ອຸປະກອນ ກໍ່ສ້າງ | F9: ລານລໍ້ | G9: 300000 | O9: =IF(C9="","",IF(C9=5,IFERROR(INDEX(code_Note1!$F$13:$F$16,MATCH(E9,code_Note1!$E$13:$E$16,0)),INDEX(code_Note1!$F$16,1)),IF(B9<code_Note1!$D$21,"No",IFERROR(VLOOKUP(C9,code_Note1!$D$3:$G$8,3,FALSE),"")))) -> No | P9: ເງິນກ້ອນເອົາມາລຶງທຶນ
B10: 45316 | C10: 2 | D10: ຄ່າກໍ່ສ້າງ ປັບປຸງສວນ | E10: ອຸປະກອນ ກໍ່ສ້າງ | F10: ລໍ້ | G10: 200000 | O10: =IF(C10="","",IF(C10=5,IFERROR(INDEX(code_Note1!$F$13:$F$16,MATCH(E10,code_Note1!$E$13:$E$16,0)),INDEX(code_Note1!$F$16,1)),IF(B10<code_Note1!$D$21,"No",IFERROR(VLOOKUP(C10,code_Note1!$D$3:$G$8,3,FALSE),"")))) -> No | P10: ເງິນກ້ອນເອົາມາລຶງທຶນ
B11: 45316 | C11: 2 | D11: ຄ່າກໍ່ສ້າງ ປັບປຸງສວນ | E11: ໄມ້ | F11: ໄມ້35 | G11: 2250000 | O11: =IF(C11="","",IF(C11=5,IFERROR(INDEX(code_Note1!$F$13:$F$16,MATCH(E11,code_Note1!$E$13:$E$16,0)),INDEX(code_Note1!$F$16,1)),IF(B11<code_Note1!$D$21,"No",IFERROR(VLOOKUP(C11,code_Note1!$D$3:$G$8,3,FALSE),"")))) -> No | P11: ເງິນກ້ອນເອົາມາລຶງທຶນ
B12: 45316 | C12: 2 | D12: ຄ່າກໍ່ສ້າງ ປັບປຸງສວນ | E12: ຫີນ ຊາຍ | F12: ຫີນ ຊາຍ | G12: 5300000 | O12: =IF(C12="","",IF(C12=5,IFERROR(INDEX(code_Note1!$F$13:$F$16,MATCH(E12,code_Note1!$E$13:$E$16,0)),INDEX(code_Note1!$F$16,1)),IF(B12<code_Note1!$D$21,"No",IFERROR(VLOOKUP(C12,code_Note1!$D$3:$G$8,3,FALSE),"")))) -> No | P12: ເງິນກ້ອນເອົາມາລຶງທຶນ
B13: 45316 | C13: 2 | D13: ຄ່າກໍ່ສ້າງ ປັບປຸງສວນ | E13: ອຸປະກອນ ກໍ່ສ້າງ | F13: ໂມ້ຫີນຊາຍ | G13: 7100000 | O13: =IF(C13="","",IF(C13=5,IFERROR(INDEX(code_Note1!$F$13:$F$16,MATCH(E13,code_Note1!$E$13:$E$16,0)),INDEX(code_Note1!$F$16,1)),IF(B13<code_Note1!$D$21,"No",IFERROR(VLOOKUP(C13,code_Note1!$D$3:$G$8,3,FALSE),"")))) -> No | P13: ເງິນກ້ອນເອົາມາລຶງທຶນ
B14: 45316 | C14: 2 | D14: ຄ່າກໍ່ສ້າງ ປັບປຸງສວນ | E14: ອຸປະກອນ ກໍ່ສ້າງ | F14: ກາແລກ | G14: 90000 | O14: =IF(C14="","",IF(C14=5,IFERROR(INDEX(code_Note1!$F$13:$F$16,MATCH(E14,code_Note1!$E$13:$E$16,0)),INDEX(code_Note1!$F$16,1)),IF(B14<code_Note1!$D$21,"No",IFERROR(VLOOKUP(C14,code_Note1!$D$3:$G$8,3,FALSE),"")))) -> No | P14: ເງິນກ້ອນເອົາມາລຶງທຶນ
B15: 45317 | C15: 3 | D15: ຄ່າບໍລິຫານ | E15: ຕລາດ | F15: ຖົ່ວດິນ ມັນເຜົາ | G15: 80000 | O15: =IF(C15="","",IF(C15=5,IFERROR(INDEX(code_Note1!$F$13:$F$16,MATCH(E15,code_Note1!$E$13:$E$16,0)),INDEX(code_Note1!$F$16,1)),IF(B15<code_Note1!$D$21,"No",IFERROR(VLOOKUP(C15,code_Note1!$D$3:$G$8,3,FALSE),"")))) -> No | P15: ລາຍງ່າຍລະຫວ່າງໄລຍະເວລາໃນການເອົາໄກ່ເຂົ້າລະໄລ່ເຂົ້າໃນການບໍລິຫານຂາດທຶນກໍາໄລໄກ່ຊຸດນັ້ນໆ
B16: 45317 | C16: 2 | D16: ຄ່າກໍ່ສ້າງ ປັບປຸງສວນ | E16: ພາຫະນະ | F16: ລົດສາມລໍ້ຂຽວ | G16: 0 | H16: 0 | I16: 784 | O16: =IF(C16="","",IF(C16=5,IFERROR(INDEX(code_Note1!$F$13:$F$16,MATCH(E16,code_Note1!$E$13:$E$16,0)),INDEX(code_Note1!$F$16,1)),IF(B16<code_Note1!$D$21,"No",IFERROR(VLOOKUP(C16,code_Note1!$D$3:$G$8,3,FALSE),"")))) -> No | P16: ເງິນກ້ອນເອົາມາລຶງທຶນ
B17: 45318 | C17: 2 | D17: ຄ່າກໍ່ສ້າງ ປັບປຸງສວນ | E17: ອຸປະກອນ ກໍ່ສ້າງ | F17: ເຊືອກ5ກໍ້ ປູນຂາວ ແລະແຮງງານ | G17: 200000 | O17: =IF(C17="","",IF(C17=5,IFERROR(INDEX(code_Note1!$F$13:$F$16,MATCH(E17,code_Note1!$E$13:$E$16,0)),INDEX(code_Note1!$F$16,1)),IF(B17<code_Note1!$D$21,"No",IFERROR(VLOOKUP(C17,code_Note1!$D$3:$G$8,3,FALSE),"")))) -> No | P17: ເງິນກ້ອນເອົາມາລຶງທຶນ
B18: 45319 | C18: 2 | D18: ຄ່າກໍ່ສ້າງ ປັບປຸງສວນ | E18: ອຸປະກອນ ກໍ່ສ້າງ | F18: ປູນຂາວ | G18: 225000 | O18: =IF(C18="","",IF(C18=5,IFERROR(INDEX(code_Note1!$F$13:$F$16,MATCH(E18,code_Note1!$E$13:$E$16,0)),INDEX(code_Note1!$F$16,1)),IF(B18<code_Note1!$D$21,"No",IFERROR(VLOOKUP(C18,code_Note1!$D$3:$G$8,3,FALSE),"")))) -> No | P18: ເງິນກ້ອນເອົາມາລຶງທຶນ
B19: 45320 | C19: 2 | D19: ຄ່າກໍ່ສ້າງ ປັບປຸງສວນ | E19: ໄມ້ | F19: ໄມ້ຕີພັງ | G19: 380000 | O19: =IF(C19="","",IF(C19=5,IFERROR(INDEX(code_Note1!$F$13:$F$16,MATCH(E19,code_Note1!$E$13:$E$16,0)),INDEX(code_Note1!$F$16,1)),IF(B19<code_Note1!$D$21,"No",IFERROR(VLOOKUP(C19,code_Note1!$D$3:$G$8,3,FALSE),"")))) -> No | P19: ເງິນກ້ອນເອົາມາລຶງທຶນ
B20: 45323 | C20: 2 | D20: ຄ່າກໍ່ສ້າງ ປັບປຸງສວນ | E20: ເລັກ | F20: ເລັກ | G20: 19360000 | O20: =IF(C20="","",IF(C20=5,IFERROR(INDEX(code_Note1!$F$13:$F$16,MATCH(E20,code_Note1!$E$13:$E$16,0)),INDEX(code_Note1!$F$16,1)),IF(B20<code_Note1!$D$21,"No",IFERROR(VLOOKUP(C20,code_Note1!$D$3:$G$8,3,FALSE),"")))) -> No | P20: ເງິນກ້ອນເອົາມາລຶງທຶນ
B21: 45323 | C21: 3 | D21: ຄ່າບໍລິຫານ | E21: ຕລາດ | F21: ເຂົ້າຈີ່ | G21: 72000 | O21: =IF(C21="","",IF(C21=5,IFERROR(INDEX(code_Note1!$F$13:$F$16,MATCH(E21,code_Note1!$E$13:$E$16,0)),INDEX(code_Note1!$F$16,1)),IF(B21<code_Note1!$D$21,"No",IFERROR(VLOOKUP(C21,code_Note1!$D$3:$G$8,3,FALSE),"")))) -> No | P21: ລາຍງ່າຍລະຫວ່າງໄລຍະເວລາໃນການເອົາໄກ່ເຂົ້າລະໄລ່ເຂົ້າໃນການບໍລິຫານຂາດທຶນກໍາໄລໄກ່ຊຸດນັ້ນໆ
B22: 45323 | C22: 3 | D22: ຄ່າບໍລິຫານ | E22: ຕລາດ | F22: ແປບຊີ | G22: 25000 | O22: =IF(C22="","",IF(C22=5,IFERROR(INDEX(code_Note1!$F$13:$F$16,MATCH(E22,code_Note1!$E$13:$E$16,0)),INDEX(code_Note1!$F$16,1)),IF(B22<code_Note1!$D$21,"No",IFERROR(VLOOKUP(C22,code_Note1!$D$3:$G$8,3,FALSE),"")))) -> No | P22: ລາຍງ່າຍລະຫວ່າງໄລຍະເວລາໃນການເອົາໄກ່ເຂົ້າລະໄລ່ເຂົ້າໃນການບໍລິຫານຂາດທຶນກໍາໄລໄກ່ຊຸດນັ້ນໆ
B23: 45323 | C23: 3 | D23: ຄ່າບໍລິຫານ | E23: ເຄື່ອງໃຊ້ ພງ | F23: ຫມວກ | G23: 140000 | O23: =IF(C23="","",IF(C23=5,IFERROR(INDEX(code_Note1!$F$13:$F$16,MATCH(E23,code_Note1!$E$13:$E$16,0)),INDEX(code_Note1!$F$16,1)),IF(B23<code_Note1!$D$21,"No",IFERROR(VLOOKUP(C23,code_Note1!$D$3:$G$8,3,FALSE),"")))) -> No | P23: ລາຍງ່າຍລະຫວ່າງໄລຍະເວລາໃນການເອົາໄກ່ເຂົ້າລະໄລ່ເຂົ້າໃນການບໍລິຫານຂາດທຶນກໍາໄລໄກ່ຊຸດນັ້ນໆ
B24: 45324 | C24: 2 | D24: ຄ່າກໍ່ສ້າງ ປັບປຸງສວນ | E24: ອຸປະກອນ ກໍ່ສ້າງ | F24: ທູບຈອດ ແລະອື່ນໆ | G24: 530000 | O24: =IF(C24="","",IF(C24=5,IFERROR(INDEX(code_Note1!$F$13:$F$16,MATCH(E24,code_Note1!$E$13:$E$16,0)),INDEX(code_Note1!$F$16,1)),IF(B24<code_Note1!$D$21,"No",IFERROR(VLOOKUP(C24,code_Note1!$D$3:$G$8,3,FALSE),"")))) -> No | P24: ເງິນກ້ອນເອົາມາລຶງທຶນ
B25: 45324 | C25: 2 | D25: ຄ່າກໍ່ສ້າງ ປັບປຸງສວນ | E25: ອຸປະກອນ ກໍ່ສ້າງ | F25: ສະເລັກທາສີເຫັລກ | G25: 140000 | O25: =IF(C25="","",IF(C25=5,IFERROR(INDEX(code_Note1!$F$13:$F$16,MATCH(E25,code_Note1!$E$13:$E$16,0)),INDEX(code_Note1!$F$16,1)),IF(B25<code_Note1!$D$21,"No",IFERROR(VLOOKUP(C25,code_Note1!$D$3:$G$8,3,FALSE),"")))) -> No | P25: ເງິນກ້ອນເອົາມາລຶງທຶນ
B26: 45324 | C26: 2 | D26: ຄ່າກໍ່ສ້າງ ປັບປຸງສວນ | E26: ຊີມັງ | F26: ຊີມັງແດງ1ຂຽວ2ຕ | G26: 5000000 | O26: =IF(C26="","",IF(C26=5,IFERROR(INDEX(code_Note1!$F$13:$F$16,MATCH(E26,code_Note1!$E$13:$E$16,0)),INDEX(code_Note1!$F$16,1)),IF(B26<code_Note1!$D$21,"No",IFERROR(VLOOKUP(C26,code_Note1!$D$3:$G$8,3,FALSE),"")))) -> No | P26: ເງິນກ້ອນເອົາມາລຶງທຶນ
B27: 45324 | C27: 3 | D27: ຄ່າບໍລິຫານ | E27: ນໍ້້າດື່ມ | F27: ນໍ້າ24ຕຸກ | G27: 216000 | O27: =IF(C27="","",IF(C27=5,IFERROR(INDEX(code_Note1!$F$13:$F$16,MATCH(E27,code_Note1!$E$13:$E$16,0)),INDEX(code_Note1!$F$16,1)),IF(B27<code_Note1!$D$21,"No",IFERROR(VLOOKUP(C27,code_Note1!$D$3:$G$8,3,FALSE),"")))) -> No | P27: ລາຍງ່າຍລະຫວ່າງໄລຍະເວລາໃນການເອົາໄກ່ເຂົ້າລະໄລ່ເຂົ້າໃນການບໍລິຫານຂາດທຶນກໍາໄລໄກ່ຊຸດນັ້ນໆ
B28: 45324 | C28: 2 | D28: ຄ່າກໍ່ສ້າງ ປັບປຸງສວນ | E28: ແຮງງານ ກໍ່ສ້າງ | F28: ແຮງງານ ລັກ19 ຈ່າຍສົດ | G28: 2000000 | O28: =IF(C28="","",IF(C28=5,IFERROR(INDEX(code_Note1!$F$13:$F$16,MATCH(E28,code_Note1!$E$13:$E$16,0)),INDEX(code_Note1!$F$16,1)),IF(B28<code_Note1!$D$21,"No",IFERROR(VLOOKUP(C28,code_Note1!$D$3:$G$8,3,FALSE),"")))) -> No | P28: ເງິນກ້ອນເອົາມາລຶງທຶນ
... B31: 45325 | C31: 2 | D31: ຄ່າກໍ່ສ້າງ ປັບປຸງສວນ | E31: ແຮງງານ ກໍ່ສ້າງ | F31: ແຮງງານ ຈອດຫັລງຕາ ຈົກດິນເກີນໂມງ | G31: 700000 | O31: =IF(C31="","",IF(C31=5,IFERROR(INDEX(code_Note1!$F$13:$F$16,MATCH(E31,code_Note1!$E$13:$E$16,0)),INDEX(code_Note1!$F$16,1)),IF(B31<code_Note1!$D$21,"No",IFERROR(VLOOKUP(C31,code_Note1!$D$3:$G$8,3,FALSE),"")))) -> No | P31: ເງິນກ້ອນເອົາມາລຶງທຶນ
B32: 45325 | C32: 2 | D32: ຄ່າກໍ່ສ້າງ ປັບປຸງສວນ | E32: ກ່ຽວກັບນໍ້າ | F32: ແທ່ງນໍ້າ | G32: 0 | H32: 0 | I32: 2000 | O32: =IF(C32="","",IF(C32=5,IFERROR(INDEX(code_Note1!$F$13:$F$16,MATCH(E32,code_Note1!$E$13:$E$16,0)),INDEX(code_Note1!$F$16,1)),IF(B32<code_Note1!$D$21,"No",IFERROR(VLOOKUP(C32,code_Note1!$D$3:$G$8,3,FALSE),"")))) -> No | P32: ເງິນກ້ອນເອົາມາລຶງທຶນ
B33: 45620 | C33: 3 | D33: ຄ່າບໍລິຫານ | E33: ຕລາດ | F33: ພັນປາ | G33: 210000 | O33: =IF(C33="","",IF(C33=5,IFERROR(INDEX(code_Note1!$F$13:$F$16,MATCH(E33,code_Note1!$E$13:$E$16,0)),INDEX(code_Note1!$F$16,1)),IF(B33<code_Note1!$D$21,"No",IFERROR(VLOOKUP(C33,code_Note1!$D$3:$G$8,3,FALSE),"")))) -> No | P33: ລາຍງ່າຍລະຫວ່າງໄລຍະເວລາໃນການເອົາໄກ່ເຂົ້າລະໄລ່ເຂົ້າໃນການບໍລິຫານຂາດທຶນກໍາໄລໄກ່ຊຸດນັ້ນໆ
B34: 45620 | C34: 1 | D34: ຄ່າໃຊ້ຈ່າຍໃນຟາມ ( ນໍ້າ, ໄຟ, ແຮງງານ) | E34: net | F34: ກ້ອງ3ຫນ່ວຍ | G34: 5550000 | O34: =IF(C34="","",IF(C34=5,IFERROR(INDEX(code_Note1!$F$13:$F$16,MATCH(E34,code_Note1!$E$13:$E$16,0)),INDEX(code_Note1!$F$16,1)),IF(B34<code_Note1!$D$21,"No",IFERROR(VLOOKUP(C34,code_Note1!$D$3:$G$8,3,FALSE),"")))) -> No | P34: ລາຍງ່າຍລະຫວ່າງໄລຍະເວລາໃນການເອົາໄກ່ເຂົ້າລະໄລ່ເຂົ້າໃນການບໍລິຫານຂາດທຶນກໍາໄລໄກ່ຊຸດນັ້ນໆ
B35: 45632 | C35: 1 | D35: ຄ່າໃຊ້ຈ່າຍໃນຟາມ ( ນໍ້າ, ໄຟ, ແຮງງານ) | E35: ຄ່າທຳນຽມ | F35: ນາຍບ້ານ copy | G35: 230000 | O35: =IF(C35="","",IF(C35=5,IFERROR(INDEX(code_Note1!$F$13:$F$16,MATCH(E35,code_Note1!$E$13:$E$16,0)),INDEX(code_Note1!$F$16,1)),IF(B35<code_Note1!$D$21,"No",IFERROR(VLOOKUP(C35,code_Note1!$D$3:$G$8,3,FALSE),"")))) -> No | P35: ລາຍງ່າຍລະຫວ່າງໄລຍະເວລາໃນການເອົາໄກ່ເຂົ້າລະໄລ່ເຂົ້າໃນການບໍລິຫານຂາດທຶນກໍາໄລໄກ່ຊຸດນັ້ນໆ
B36: 45645 | C36: 1 | D36: ຄ່າໃຊ້ຈ່າຍໃນຟາມ ( ນໍ້າ, ໄຟ, ແຮງງານ) | E36: net | F36: ເນັດ ລັກ19 | G36: 165000 | O36: =IF(C36="","",IF(C36=5,IFERROR(INDEX(code_Note1!$F$13:$F$16,MATCH(E36,code_Note1!$E$13:$E$16,0)),INDEX(code_Note1!$F$16,1)),IF(B36<code_Note1!$D$21,"No",IFERROR(VLOOKUP(C36,code_Note1!$D$3:$G$8,3,FALSE),"")))) -> No | P36: ລາຍງ່າຍລະຫວ່າງໄລຍະເວລາໃນການເອົາໄກ່ເຂົ້າລະໄລ່ເຂົ້າໃນການບໍລິຫານຂາດທຶນກໍາໄລໄກ່ຊຸດນັ້ນໆ
B37: 45653 | C37: 1 | D37: ຄ່າໃຊ້ຈ່າຍໃນຟາມ ( ນໍ້າ, ໄຟ, ແຮງງານ) | E37: ຄ່າທຳນຽມ | F37: ບົດບັນທຶກສຳລວດ ມາ5ຄົນ | G37: 2100000 | O37: =IF(C37="","",IF(C37=5,IFERROR(INDEX(code_Note1!$F$13:$F$16,MATCH(E37,code_Note1!$E$13:$E$16,0)),INDEX(code_Note1!$F$16,1)),IF(B37<code_Note1!$D$21,"No",IFERROR(VLOOKUP(C37,code_Note1!$D$3:$G$8,3,FALSE),"")))) -> No | P37: ລາຍງ່າຍລະຫວ່າງໄລຍະເວລາໃນການເອົາໄກ່ເຂົ້າລະໄລ່ເຂົ້າໃນການບໍລິຫານຂາດທຶນກໍາໄລໄກ່ຊຸດນັ້ນໆ
B38: 45660 | C38: 2 | D38: ຄ່າກໍ່ສ້າງ ປັບປຸງສວນ | E38: ພັດລົມ | F38: ຈ່າຍຄ່າໃຫ່ຍ ເຄິ່ງຄ່າກ່ອນ ໄວ້ໃສ່ຄອກຢູລັກ19 ຈໍານວນ36ໜ່ວຍ | G38: 36000000 | O38: =IF(C38="","",IF(C38=5,IFERROR(INDEX(code_Note1!$F$13:$F$16,MATCH(E38,code_Note1!$E$13:$E$16,0)),INDEX(code_Note1!$F$16,1)),IF(B38<code_Note1!$D$21,"No",IFERROR(VLOOKUP(C38,code_Note1!$D$3:$G$8,3,FALSE),"")))) -> No | P38: ເງິນກ້ອນເອົາມາລຶງທຶນ
B39: 45667 | C39: 1 | D39: ຄ່າໃຊ້ຈ່າຍໃນຟາມ ( ນໍ້າ, ໄຟ, ແຮງງານ) | E39: vac | F39: ແຮງງານດາດປາກໄກ່ ອ້າຍຫອມສົ່ງຄົນກໍ່ສ້າງຊ່ວຍ2ຄອກລຸ່ມ | G39: 1200000 | O39: =IF(C39="","",IF(C39=5,IFERROR(INDEX(code_Note1!$F$13:$F$16,MATCH(E39,code_Note1!$E$13:$E$16,0)),INDEX(code_Note1!$F$16,1)),IF(B39<code_Note1!$D$21,"No",IFERROR(VLOOKUP(C39,code_Note1!$D$3:$G$8,3,FALSE),"")))) -> No | P39: ລາຍງ່າຍລະຫວ່າງໄລຍະເວລາໃນການເອົາໄກ່ເຂົ້າລະໄລ່ເຂົ້າໃນການບໍລິຫານຂາດທຶນກໍາໄລໄກ່ຊຸດນັ້ນໆ
B40: 45669 | C40: 1 | D40: ຄ່າໃຊ້ຈ່າຍໃນຟາມ ( ນໍ້າ, ໄຟ, ແຮງງານ) | E40: vac | F40: ສັກວັກຊິນ | G40: 3100000 | O40: =IF(C40="","",IF(C40=5,IFERROR(INDEX(code_Note1!$F$13:$F$16,MATCH(E40,code_Note1!$E$13:$E$16,0)),INDEX(code_Note1!$F$16,1)),IF(B40<code_Note1!$D$21,"No",IFERROR(VLOOKUP(C40,code_Note1!$D$3:$G$8,3,FALSE),"")))) -> No | P40: ລາຍງ່າຍລະຫວ່າງໄລຍະເວລາໃນການເອົາໄກ່ເຂົ້າລະໄລ່ເຂົ້າໃນການບໍລິຫານຂາດທຶນກໍາໄລໄກ່ຊຸດນັ້ນໆ
B41: 45672 | C41: 1 | D41: ຄ່າໃຊ້ຈ່າຍໃນຟາມ ( ນໍ້າ, ໄຟ, ແຮງງານ) | E41: net | F41: ເນັດ ລັກ19 | G41: 120000 | O41: =IF(C41="","",IF(C41=5,IFERROR(INDEX(code_Note1!$F$13:$F$16,MATCH(E41,code_Note1!$E$13:$E$16,0)),INDEX(code_Note1!$F$16,1)),IF(B41<code_Note1!$D$21,"No",IFERROR(VLOOKUP(C41,code_Note1!$D$3:$G$8,3,FALSE),"")))) -> No | P41: ລາຍງ່າຍລະຫວ່າງໄລຍະເວລາໃນການເອົາໄກ່ເຂົ້າລະໄລ່ເຂົ້າໃນການບໍລິຫານຂາດທຶນກໍາໄລໄກ່ຊຸດນັ້ນໆ
B42: 45675 | C42: 2 | D42: ຄ່າກໍ່ສ້າງ ປັບປຸງສວນ | E42: ເສົາ | F42: ຈໍາເສົາ | G42: 0 | I42: 1000 | O42: =IF(C42="","",IF(C42=5,IFERROR(INDEX(code_Note1!$F$13:$F$16,MATCH(E42,code_Note1!$E$13:$E$16,0)),INDEX(code_Note1!$F$16,1)),IF(B42<code_Note1!$D$21,"No",IFERROR(VLOOKUP(C42,code_Note1!$D$3:$G$8,3,FALSE),"")))) -> No | P42: ເງິນກ້ອນເອົາມາລຶງທຶນ
...

Sheet code_Note1
A1: Code | B1: Note | D1: ລາຍການລາຍຈ່າຍຂອງຟາມ
A2: 1 | B2: net | D2: Code | E2: Name | F2: ໄລ່ເຂົ້າກໍາໄລແຕ່ລະງວດບໍ? | G2: Note
A3: 1 | B3: ຄ່າທຳນຽມ | D3: 1 | E3: ຄ່າໃຊ້ຈ່າຍໃນຟາມ ( ນໍ້າ, ໄຟ, ແຮງງານ) | F3: Yes | G3: ລາຍງ່າຍລະຫວ່າງໄລຍະເວລາໃນການເອົາໄກ່ເຂົ້າລະໄລ່ເຂົ້າໃນການບໍລິຫານຂາດທຶນກໍາໄລໄກ່ຊຸດນັ້ນໆ | K3: 5
A4: 1 | B4: vac | D4: 2 | E4: ຄ່າກໍ່ສ້າງ ປັບປຸງສວນ | F4: No | G4: ເງິນກ້ອນເອົາມາລຶງທຶນ
A5: 1 | B5: ແຮງງານນໍ້າມັນເອົາແກບມາ | D5: 3 | E5: ຄ່າບໍລິຫານ | F5: yes | G5: ລາຍງ່າຍລະຫວ່າງໄລຍະເວລາໃນການເອົາໄກ່ເຂົ້າລະໄລ່ເຂົ້າໃນການບໍລິຫານຂາດທຶນກໍາໄລໄກ່ຊຸດນັ້ນໆ
A6: 1 | B6: ຄ່າໄຟຟ້າ | D6: ພໍ່ | E6: ຄ່າໃຊ້ຈ່າຍພໍ່ອອກກ່ອນ | F6: No | G6: ເງິນກ້ອນເອົາມາລຶງທຶນ ແຕ່ແຍກເມື່ອຕ້ອງການຈະຊໍາລະຄືນ ເມື່ອຊໍາລະແລ້ວໃຫ້ລົບຍອດສະສົມ
A7: 1 | B7: ຍົກແກບດິບ | D7: ແມ່ | E7: ຄ່າໃຊ້ຈ່າຍແມ່ອອກກ່ອນ | F7: No | G7: ເງິນກ້ອນເອົາມາລຶງທຶນ ແຕ່ແຍກເມື່ອຕ້ອງການຈະຊໍາລະຄືນ ເມື່ອຊໍາລະແລ້ວໃຫ້ລົບຍອດສະສົມ
A8: 1 | B8: ແກບດິບ | D8: 4 | E8: ລາຍຈ່າຍອື່ນໆ | F8: Yes/N0 | G8: ລາຍງ່າຍອື່ນໆ ທີ່ອອກໃນນາມຟາມ
A9: 1 | B9: ແກບ 2000
A10: 1 | B10: ເປົາແກບ
A11: 1 | B11: Gas | D11: ລາຍການລາຍຮັບຂອງຟາມ
A12: 1 | B12: ຄ່ານໍ້າປະປາ | D12: Code | E12: Name | F12: ໄລ່ເຂົ້າກໍາໄລແຕ່ລະງວດບໍ? | G12: Note
A13: 1 | B13: ອຸປະກອນຕັກແກບ | D13: 1 | E13: ຂາຍໄກ່ | F13: yes | G13: ລາຍງ່າຍລະຫວ່າງໄລຍະເວລາໃນການເອົາໄກ່ເຂົ້າລະໄລ່ເຂົ້າໃນການບໍລິຫານຂາດທຶນກໍາໄລໄກ່ຊຸດນັ້ນໆ
A14: 1 | B14: ອານາໄມຄອກ | D14: 2 | E14: ຂາຍໄຂ່ | F14: Yes | G14: ເງິນກ້ອນເອົາມາລຶງທຶນ
A15: 1 | B15: ແກບ 3000 | D15: 3 | E15: ຂາຍແກບ | F15: Yes | G15: ເງິນກ້ອນເອົາມາລຶງທຶນ
A16: 1 | B16: ແກບ 1000 | D16: 4 | E16: ລາຍຮັບອື່ນ | F16: Yes/No | G16: ເປັນລາຍຮັບອື່ນໆ ຕາມລະດຸການຂອງສວນ ເຊັ່ນ: ຂາຍໝາກມ່ວງ, ໝໍ່ໄມ້, …
A17: 1 | B17: ຫວຽດໄໝ
A18: 1 | B18: ແຮງງານ ຍົກແກບອອກດ່ວນ
A19: 1 | B19: ສ້ອມແປງ
A20: 1 | B20: Vac ແຮງງານຈ່າຍເພີ່ມ
A21: 1 | B21: ຂາຍແກບ ຈ້າງຍົກ | D21: 45927 | E21: ງວດ 1 | F21: ງວດ1 ຄອກ 123 | G21: 30,588.00ໂຕ
A22: 2 | B22: ຊີມັງ ເລັກ | D22: 45994 | E22: ງວດ 2 | F22: ງວດ2 ຄອກ 45 | G22: 22,012.00ໂຕ
A23: 2 | B23: ອຸປະກອນ ກໍ່ສ້າງ | D23: 46081 | E23: ງວດ 3 | F23: ງວດ3 ຄອກ 123 | G23: 29,545.00ໂຕ
A24: 2 | B24: ໄມ້
A25: 2 | B25: ຫີນ ຊາຍ
A26: 2 | B26: ພາຫະນະ
A27: 2 | B27: ເລັກ
A28: 2 | B28: ຊີມັງ
A29: 2 | B29: ແຮງງານ ກໍ່ສ້າງ
A30: 2 | B30: ກ່ຽວກັບນໍ້າ
A31: 2 | B31: ພັດລົມ
A32: 2 | B32: ເສົາ
A33: 2 | B33: ປູກຕົ້ນໄມ້
A34: 2 | B34: ປັບດິນ
A35: 2 | B35: ອາລູຊິງ
... A62: 5 | B62: ເຟືອງ
A63: Family ພ | B63: ແຮງງານ ກໍ່ສ້າງ
A64: Family ພ | B64: ກຳແພງ
A65: Family ພ | B65: ທໍ່
A66: Family ພ | B66: ອຸປະກອນ ກໍ່ສ້າງ
...
